Workbook
Name Slicer_Country: #N/A
Name Slicer_Name: #N/A

Sheet global_freelancer_raw data
A1: freelancer_ID | B1: name | C1: gender | D1: Column1 | E1: age | F1: country | G1: language | H1: primary_skill | I1: years_of_experience | J1: hourly_rate (USD) | K1: rating | L1: is_active | M1: client_satisfaction | N1: Notes | O1: Status | P1: no of projects | Q1: duration_months
A2: FL250001 | B2: Ms. Nicole Kidd | C2: f | D2: Female | E2: 52 | F2: Italy | G2: Italian | H2: Blockchain Development | I2: 11 | J2: 100 | L2: 0 | N2: Reviewed | O2: On Hold | P2: 13 | Q2: 6
A3: FL250002 | B3: Vanessa Garcia | C3: FEMALE | D3: Female | E3: 52 | F3: Australia | G3: English | H3: Mobile Apps | I3: 34 | J3: USD 100 | K3: 3.3 | L3: 1 | M3: 0.84 | N3: Reviewed | O3: Completed | P3: 10 | Q3: 7
A4: FL250003 | B4: Juan Nelson | C4: male | D4: Male | E4: 53 | F4: Germany | G4: Germany | H4: Graphic Design | I4: 31 | J4: 50 | K4: 0 | L4: N | M4: 0.71 | N4: Reviewed | O4: Active | P4: 16 | Q4: 16
A5: FL250004 | B5: Amanda Spencer | C5: F | D5: Female | E5: 38 | F5: Australia | G5: English | H5: Web Development | I5: 4 | J5: $40 | K5: 1.5 | L5: N | M5: 0.9 | N5: Reviewed | O5: Completed | P5: 5 | Q5: 1
A6: FL250005 | B6: Lynn Curtis DDS | C6: female | D6: Female | E6: 53 | F6: Germany | G6: Germany | I6: 27 | J6: 30 | K6: 4.8 | L6: 0 | M6: 0.83 | N6: Reviewed | O6: On Hold | P6: 13 | Q6: 3
A7: FL250006 | B7: Lisa Johnson | C7: female | D7: Female | E7: 59 | F7: Netherlands | G7: Dutch | H7: AI | I7: 14 | J7: $30 | K7: 2.4 | L7: FALSE | N7: Urgent | O7: Active | P7: 8 | Q7: 3
A8: FL250007 | B8: Eric Myers | C8: m | D8: Male | E8: 52 | F8: Indonesia | G8: Indonesian | H8: Data Analysis | I8: 10 | J8: USD 75 | K8: 3.1 | L8: 0 | M8: 0.94 | N8: Reviewed | O8: On Hold | P8: 10 | Q8: 3
A9: FL250008 | B9: Ricky Graham | C9: male | D9: Male | E9: 43 | F9: Italy | G9: Italian | H9: Blockchain Development | I9: 14 | J9: USD 40 | K9: 4.6 | L9: FALSE | M9: 0.94 | N9: Urgent | O9: On Hold | P9: 7 | Q9: 10
A10: FL250009 | B10: Sean Martin | C10: male | D10: Male | E10: 26 | F10: US | G10: English | H10: Blockchain Development | I10: 4 | K10: 4 | L10: TRUE | M10: 0.76 | N10: Reviewed | O10: Inactive | P10: 2 | Q10: 4
A11: FL250010 | B11: Matthew Lloyd | C11: MALE | D11: Male | E11: 52 | F11: Turkey | G11: Turkish | H11: AI | I11: 22 | J11: $50 | L11: 1 | N11: Pending | O11: Active | P11: 16 | Q11: 5
A12: FL250011 | B12: Gavin Randall | C12: m | D12: Male | E12: 40 | F12: UK | G12: English | H12: Data Analysis | I12: 17 | J12: 40 | K12: 3.6 | L12: yes | M12: 0.77 | N12: Follow-up | O12: Inactive | P12: 20 | Q12: 5
A13: FL250012 | B13: Michelle Curtis | C13: FEMALE | D13: Female | E13: 55 | F13: Argentina | G13: Spanish | H13: UI/UX Design | I13: 15 | L13: Y | M13: 0.86 | N13: Urgent | O13: Active | P13: 13 | Q13: 4
A14: FL250013 | B14: Alice Schneider | C14: Female | D14: Female | E14: 57 | F14: UK | G14: English | H14: Cybersecurity | I14: 18 | K14: 2 | L14: 0 | M14: 0.86 | N14: Reviewed | O14: On Hold | P14: 16 | Q14: 15
A15: FL250014 | B15: Phillip Shelton | C15: MALE | D15: Male | E15: 38 | G15: Spanish | H15: Graphic Design | I15: 20 | J15: USD 75 | K15: 2.9 | L15: 1 | M15: 0.93 | N15: Pending | O15: On Hold | P15: 17 | Q15: 12
A16: FL250015 | B16: Edward Ferguson | C16: MALE | D16: Male | E16: 50 | F16: Germany | G16: Germany | H16: Data Analysis | I16: 22 | J16: 75 | K16: 3.7 | L16: 1 | M16: 0.7 | N16: Follow-up | O16: Completed | P16: 14 | Q16: 6
A17: FL250016 | B17: Wyatt Stout | C17: m | D17: Male | E17: 42 | F17: Japan | G17: Japanese | I17: 0 | J17: $30 | K17: 1.2 | L17: 0 | M17: 0.69 | N17: Urgent | O17: Active | P17: 5 | Q17: 2
A18: FL250017 | B18: Laura Johnson | C18: Female | D18: Female | E18: 39 | F18: Australia | G18: English | H18: DevOps | I18: 13 | J18: $30 | K18: 2.5 | L18: FALSE | M18: 0.6 | N18: Follow-up | O18: Inactive | P18: 7 | Q18: 1
A19: FL250018 | B19: Scott Burns | C19: M | D19: Male | E19: 56 | F19: India | G19: Hindi | H19: Blockchain Development | M19: 0.87 | N19: Pending | O19: Completed | P19: 1 | Q19: 2
A20: FL250019 | B20: Tyler Aguirre | C20: Male | D20: Male | E20: 56 | F20: US | G20: English | H20: UI/UX Design | I20: 31 | J20: USD 50 | K20: 1.1 | L20: N | M20: 0.75 | N20: Urgent | O20: Completed | P20: 13 | Q20: 3
A21: FL250020 | B21: Matthew Lawson | C21: Male | D21: Male | E21: 57 | F21: Italy | G21: Italian | H21: Web Development | I21: 3 | J21: USD 100 | K21: 1.8 | L21: yes | M21: 0.68 | N21: Follow-up | O21: Completed | P21: 1 | Q21: 1
A22: FL250021 | B22: James Cherry | C22: Male | D22: Male | F22: Indonesia | G22: Indonesian | H22: AI | I22: 9 | J22: 50 | K22: 1.8 | L22: FALSE | M22: 0.65 | N22: Reviewed | O22: Inactive | P22: 15 | Q22: 6
A23: FL250022 | B23: Samuel Sanford | C23: m | D23: Male | E23: 51 | F23: Japan | G23: Japanese | H23: DevOps | K23: 2.4 | L23: N | M23: 0.69 | N23: Urgent | O23: Completed | P23: 3 | Q23: 5
A24: FL250023 | B24: Cesar Greene | C24: m | D24: Male | E24: 51 | F24: Brazil | G24: Portuguese | H24: Cybersecurity | I24: 21 | J24: USD 30 | K24: 4.7 | L24: N | N24: Follow-up | O24: Inactive | P24: 14 | Q24: 2
A25: FL250024 | B25: Melanie Carter | C25: female | D25: Female | E25: 51 | F25: South Korea | G25: Korean | H25: Machine Learning | I25: 15 | J25: $50 | K25: 1.3 | L25: 1 | M25: 1 | N25: Pending | O25: Completed | P25: 9 | Q25: 3
A26: FL250025 | B26: Jennifer Martin | C26: f | D26: Female | E26: 54 | F26: Indonesia | G26: Indonesian | H26: Machine Learning | I26: 13 | J26: 75 | K26: 2.9 | M26: 92 | N26: Pending | O26: Inactive | P26: 15 | Q26: 3
A27: FL250026 | B27: Anna Mccann | C27: FEMALE | D27: Female | E27: 22 | F27: South Korea | G27: Korean | H27: DevOps | I27: 0 | J27: USD 30 | K27: 1.2 | L27: 1 | M27: 0.7 | N27: Urgent | O27: On Hold | P27: 5 | Q27: 2
A28: FL250027 | B28: Marissa Bass | C28: female | D28: Female | E28: 34 | F28: Japan | G28: Japanese | H28: Blockchain Development | I28: 8 | J28: $20 | K28: 0 | L28: TRUE | M28: 0.89 | N28: Follow-up | O28: On Hold | P28: 6 | Q28: 1
A29: FL250028 | B29: Alexis Day | C29: Female | D29: Female | E29: 36 | F29: Russia | G29: Russian | H29: Graphic Design | I29: 11 | K29: 1.8 | L29: Y | M29: 0.86 | N29: Urgent | O29: On Hold | P29: 12 | Q29: 4
A30: FL250029 | B30: Megan Jones | C30: female | D30: Female | E30: 47 | F30: Canada | G30: English | H30: AI | I30: 22 | J30: 30 | K30: 1.3 | L30: 0 | M30: 0.62 | N30: Urgent | O30: On Hold | P30: 14 | Q30: 2
A31: FL250030 | B31: Lori Smith | C31: FEMALE | D31: Female | E31: 41 | F31: Netherlands | G31: Dutch | H31: Data Analysis | I31: 14 | J31: USD 75 | K31: 1.2 | L31: 0 | N31: Follow-up | O31: On Hold | P31: 6 | Q31: 5
A32: FL250031 | B32: Eric Carpenter | C32: Male | D32: Male | E32: 22 | F32: Netherlands | G32: Dutch | H32: DevOps | I32: 4 | K32: 1 | L32: yes | N32: Follow-up | O32: Completed | P32: 3 | Q32: 1
A33: FL250032 | B33: Timothy Daniels | C33: Male | D33: Male | E33: 38 | F33: France | G33: French | H33: Machine Learning | I33: 19 | J33: USD 100 | K33: 4.2 | L33: N | M33: 0.68 | N33: Reviewed | O33: Completed | P33: 10 | Q33: 10
A34: FL250033 | B34: Robert Nelson | C34: M | D34: Male | E34: 46 | F34: Egypt | G34: Arabic | H34: AI | I34: 9 | J34: 20 | K34: 1.4 | L34: TRUE | M34: 0.76 | N34: Follow-up | O34: Completed | P34: 13 | Q34: 6
A35: FL250034 | B35: Michael Anderson | C35: male | D35: Male | F35: South Korea | G35: Korean | H35: AI | I35: 9 | J35: 40 | K35: 2.4 | L35: yes | M35: 82 | N35: Pending | O35: Inactive | P35: 15 | Q35: 3
A36: FL250035 | B36: Jessica Snyder | C36: FEMALE | D36: Female | E36: 54 | F36: US | G36: English | H36: Web Development | I36: 32 | J36: 75 | K36: 1 | L36: yes | M36: 0.81 | N36: Urgent | O36: Inactive | P36: 18 | Q36: 10
A37: FL250036 | B37: Emily Daniels | C37: female | D37: Female | E37: 52 | F37: South Korea | G37: Korean | I37: 28 | J37: $20 | L37: 0 | N37: Urgent | O37: Inactive | P37: 18 | Q37: 2
A38: FL250037 | B38: Jamie Ramirez | C38: f | D38: Female | E38: 42 | F38: Japan | G38: Japanese | H38: Mobile Apps | I38: 6 | J38: 40 | L38: 0 | M38: 0.63 | N38: Pending | O38: Inactive | P38: 15 | Q38: 6
A39: FL250038 | B39: Amy Harrison | C39: F | D39: Female | E39: 29 | F39: Netherlands | G39: Dutch | H39: Graphic Design | I39: 10 | J39: 40 | K39: 2.2 | L39: N | M39: 0.67 | N39: Follow-up | O39: On Hold | P39: 10 | Q39: 9
A40: FL250039 | B40: Melinda White | C40: F | D40: Female | E40: 42 | F40: South Africa | G40: Afrikaans | H40: Mobile Apps | I40: 23 | J40: 50 | K40: 3.2 | L40: yes | N40: Pending | O40: On Hold | P40: 13 | Q40: 3
...

Sheet global_freelancer Cleaned data
A1: Freelancer ID | B1: Name | C1: Gender | D1: Age | E1: Country | F1: Language | G1: Primary_skill | H1: Years_of_Experience | I1: Hourly_rate (USD) | J1: Rating | K1: Is_active | L1: Client Satisfaction | M1: Notes | N1: Status | O1: No of projects | P1: IF Condition | Q1: Duration Months
A2: FL250001 | B2: Ms. Nicole Kidd | C2: Female | D2: 52 | E2: Italy | F2: Italian | G2: Blockchain Development | H2: 11 | I2: 100 | J2: Not Mentioned | K2: 0 | L2: Not Mentioned | M2: Reviewed | N2: On Hold | O2: 13 | P2: =IF(global_freelancer_raw[[#This Row],[No of projects ]]<=5,"Entry level","Well Experienced") -> Well Experienced | Q2: 6
A3: FL250002 | B3: Vanessa Garcia | C3: Female | D3: 52 | E3: Australia | F3: English | G3: Mobile Apps | H3: 34 | I3: USD 100 | J3: 3.3 | K3: 1 | L3: 0.84 | M3: Reviewed | N3: Completed | O3: 10 | P3: =IF(global_freelancer_raw[[#This Row],[No of projects ]]<=5,"Entry level","Well Experienced") -> Well Experienced | Q3: 7
A4: FL250003 | B4: Juan Nelson | C4: Male | D4: 53 | E4: Germany | F4: Germany | G4: Graphic Design | H4: 31 | I4: 50 | J4: 0 | K4: N | L4: 0.71 | M4: Reviewed | N4: Active | O4: 16 | P4: =IF(global_freelancer_raw[[#This Row],[No of projects ]]<=5,"Entry level","Well Experienced") -> Well Experienced | Q4: 16
A5: FL250004 | B5: Amanda Spencer | C5: Female | D5: 38 | E5: Australia | F5: English | G5: Web Development | H5: 4 | I5: $40 | J5: 1.5 | K5: N | L5: 0.9 | M5: Reviewed | N5: Completed | O5: 5 | P5: =IF(global_freelancer_raw[[#This Row],[No of projects ]]<=5,"Entry level","Well Experienced") -> Entry level | Q5: 1
A6: FL250005 | B6: Lynn Curtis DDS | C6: Female | D6: 53 | E6: Germany | F6: Germany | G6: Not Mentioned | H6: 27 | I6: 30 | J6: 4.8 | K6: 0 | L6: 0.83 | M6: Reviewed | N6: On Hold | O6: 13 | P6: =IF(global_freelancer_raw[[#This Row],[No of projects ]]<=5,"Entry level","Well Experienced") -> Well Experienced | Q6: 3
A7: FL250006 | B7: Lisa Johnson | C7: Female | D7: 59 | E7: Netherlands | F7: Dutch | G7: AI | H7: 14 | I7: $30 | J7: 2.4 | K7: FALSE | L7: Not Mentioned | M7: Urgent | N7: Active | O7: 8 | P7: =IF(global_freelancer_raw[[#This Row],[No of projects ]]<=5,"Entry level","Well Experienced") -> Well Experienced | Q7: 3
A8: FL250007 | B8: Eric Myers | C8: Male | D8: 52 | E8: Indonesia | F8: Indonesian | G8: Data Analysis | H8: 10 | I8: USD 75 | J8: 3.1 | K8: 0 | L8: 0.94 | M8: Reviewed | N8: On Hold | O8: 10 | P8: =IF(global_freelancer_raw[[#This Row],[No of projects ]]<=5,"Entry level","Well Experienced") -> Well Experienced | Q8: 3
A9: FL250008 | B9: Ricky Graham | C9: Male | D9: 43 | E9: Italy | F9: Italian | G9: Blockchain Development | H9: 14 | I9: USD 40 | J9: 4.6 | K9: FALSE | L9: 0.94 | M9: Urgent | N9: On Hold | O9: 7 | P9: =IF(global_freelancer_raw[[#This Row],[No of projects ]]<=5,"Entry level","Well Experienced") -> Well Experienced | Q9: 10
A10: FL250009 | B10: Sean Martin | C10: Male | D10: 26 | E10: US | F10: English | G10: Blockchain Development | H10: 4 | I10: Not given | J10: 4 | K10: TRUE | L10: 0.76 | M10: Reviewed | N10: Inactive | O10: 2 | P10: =IF(global_freelancer_raw[[#This Row],[No of projects ]]<=5,"Entry level","Well Experienced") -> Entry level | Q10: 4
A11: FL250010 | B11: Matthew Lloyd | C11: Male | D11: 52 | E11: Turkey | F11: Turkish | G11: AI | H11: 22 | I11: $50 | J11: Not Mentioned | K11: 1 | L11: Not Mentioned | M11: Pending | N11: Active | O11: 16 | P11: =IF(global_freelancer_raw[[#This Row],[No of projects ]]<=5,"Entry level","Well Experienced") -> Well Experienced | Q11: 5
A12: FL250011 | B12: Gavin Randall | C12: Male | D12: 40 | E12: UK | F12: English | G12: Data Analysis | H12: 17 | I12: 40 | J12: 3.6 | K12: yes | L12: 0.77 | M12: Follow-up | N12: Inactive | O12: 20 | P12: =IF(global_freelancer_raw[[#This Row],[No of projects ]]<=5,"Entry level","Well Experienced") -> Well Experienced | Q12: 5
A13: FL250012 | B13: Michelle Curtis | C13: Female | D13: 55 | E13: Argentina | F13: Spanish | G13: UI/UX Design | H13: 15 | I13: Not given | J13: Not Mentioned | K13: Y | L13: 0.86 | M13: Urgent | N13: Active | O13: 13 | P13: =IF(global_freelancer_raw[[#This Row],[No of projects ]]<=5,"Entry level","Well Experienced") -> Well Experienced | Q13: 4
A14: FL250013 | B14: Alice Schneider | C14: Female | D14: 57 | E14: UK | F14: English | G14: Cybersecurity | H14: 18 | I14: Not given | J14: 2 | K14: 0 | L14: 0.86 | M14: Reviewed | N14: On Hold | O14: 16 | P14: =IF(global_freelancer_raw[[#This Row],[No of projects ]]<=5,"Entry level","Well Experienced") -> Well Experienced | Q14: 15
A15: FL250014 | B15: Phillip Shelton | C15: Male | D15: 38 | E15: Not Mentioned | F15: Spanish | G15: Graphic Design | H15: 20 | I15: USD 75 | J15: 2.9 | K15: 1 | L15: 0.93 | M15: Pending | N15: On Hold | O15: 17 | P15: =IF(global_freelancer_raw[[#This Row],[No of projects ]]<=5,"Entry level","Well Experienced") -> Well Experienced | Q15: 12
A16: FL250015 | B16: Edward Ferguson | C16: Male | D16: 50 | E16: Germany | F16: Germany | G16: Data Analysis | H16: 22 | I16: 75 | J16: 3.7 | K16: 1 | L16: 0.7 | M16: Follow-up | N16: Completed | O16: 14 | P16: =IF(global_freelancer_raw[[#This Row],[No of projects ]]<=5,"Entry level","Well Experienced") -> Well Experienced | Q16: 6
A17: FL250016 | B17: Wyatt Stout | C17: Male | D17: 42 | E17: Japan | F17: Japanese | G17: Not Mentioned | H17: 0 | I17: $30 | J17: 1.2 | K17: 0 | L17: 0.69 | M17: Urgent | N17: Active | O17: 5 | P17: =IF(global_freelancer_raw[[#This Row],[No of projects ]]<=5,"Entry level","Well Experienced") -> Entry level | Q17: 2
A18: FL250017 | B18: Laura Johnson | C18: Female | D18: 39 | E18: Australia | F18: English | G18: DevOps | H18: 13 | I18: $30 | J18: 2.5 | K18: FALSE | L18: 0.6 | M18: Follow-up | N18: Inactive | O18: 7 | P18: =IF(global_freelancer_raw[[#This Row],[No of projects ]]<=5,"Entry level","Well Experienced") -> Well Experienced | Q18: 1
A19: FL250018 | B19: Scott Burns | C19: Male | D19: 56 | E19: India | F19: Hindi | G19: Blockchain Development | H19: Not Mentioned | I19: Not given | J19: Not Mentioned | K19: Not Mentioned | L19: 0.87 | M19: Pending | N19: Completed | O19: 1 | P19: =IF(global_freelancer_raw[[#This Row],[No of projects ]]<=5,"Entry level","Well Experienced") -> Entry level | Q19: 2
A20: FL250019 | B20: Tyler Aguirre | C20: Male | D20: 56 | E20: US | F20: English | G20: UI/UX Design | H20: 31 | I20: USD 50 | J20: 1.1 | K20: N | L20: 0.75 | M20: Urgent | N20: Completed | O20: 13 | P20: =IF(global_freelancer_raw[[#This Row],[No of projects ]]<=5,"Entry level","Well Experienced") -> Well Experienced | Q20: 3
A21: FL250020 | B21: Matthew Lawson | C21: Male | D21: 57 | E21: Italy | F21: Italian | G21: Web Development | H21: 3 | I21: USD 100 | J21: 1.8 | K21: yes | L21: 0.68 | M21: Follow-up | N21: Completed | O21: 1 | P21: =IF(global_freelancer_raw[[#This Row],[No of projects ]]<=5,"Entry level","Well Experienced") -> Entry level | Q21: 1
A22: FL250021 | B22: James Cherry | C22: Male | D22: Not given | E22: Indonesia | F22: Indonesian | G22: AI | H22: 9 | I22: 50 | J22: 1.8 | K22: FALSE | L22: 0.65 | M22: Reviewed | N22: Inactive | O22: 15 | P22: =IF(global_freelancer_raw[[#This Row],[No of projects ]]<=5,"Entry level","Well Experienced") -> Well Experienced | Q22: 6
A23: FL250022 | B23: Samuel Sanford | C23: Male | D23: 51 | E23: Japan | F23: Japanese | G23: DevOps | H23: Not Mentioned | I23: Not given | J23: 2.4 | K23: N | L23: 0.69 | M23: Urgent | N23: Completed | O23: 3 | P23: =IF(global_freelancer_raw[[#This Row],[No of projects ]]<=5,"Entry level","Well Experienced") -> Entry level | Q23: 5
A24: FL250023 | B24: Cesar Greene | C24: Male | D24: 51 | E24: Brazil | F24: Portuguese | G24: Cybersecurity | H24: 21 | I24: USD 30 | J24: 4.7 | K24: N | L24: Not Mentioned | M24: Follow-up | N24: Inactive | O24: 14 | P24: =IF(global_freelancer_raw[[#This Row],[No of projects ]]<=5,"Entry level","Well Experienced") -> Well Experienced | Q24: 2
A25: FL250024 | B25: Melanie Carter | C25: Female | D25: 51 | E25: South Korea | F25: Korean | G25: Machine Learning | H25: 15 | I25: $50 | J25: 1.3 | K25: 1 | L25: 1 | M25: Pending | N25: Completed | O25: 9 | P25: =IF(global_freelancer_raw[[#This Row],[No of projects ]]<=5,"Entry level","Well Experienced") -> Well Experienced | Q25: 3
A26: FL250025 | B26: Jennifer Martin | C26: Female | D26: 54 | E26: Indonesia | F26: Indonesian | G26: Machine Learning | H26: 13 | I26: 75 | J26: 2.9 | K26: Not Mentioned | L26: 92 | M26: Pending | N26: Inactive | O26: 15 | P26: =IF(global_freelancer_raw[[#This Row],[No of projects ]]<=5,"Entry level","Well Experienced") -> Well Experienced | Q26: 3
A27: FL250026 | B27: Anna Mccann | C27: Female | D27: 22 | E27: South Korea | F27: Korean | G27: DevOps | H27: 0 | I27: USD 30 | J27: 1.2 | K27: 1 | L27: 0.7 | M27: Urgent | N27: On Hold | O27: 5 | P27: =IF(global_freelancer_raw[[#This Row],[No of projects ]]<=5,"Entry level","Well Experienced") -> Entry level | Q27: 2
A28: FL250027 | B28: Marissa Bass | C28: Female | D28: 34 | E28: Japan | F28: Japanese | G28: Blockchain Development | H28: 8 | I28: $20 | J28: 0 | K28: TRUE | L28: 0.89 | M28: Follow-up | N28: On Hold | O28: 6 | P28: =IF(global_freelancer_raw[[#This Row],[No of projects ]]<=5,"Entry level","Well Experienced") -> Well Experienced | Q28: 1
A29: FL250028 | B29: Alexis Day | C29: Female | D29: 36 | E29: Russia | F29: Russian | G29: Graphic Design | H29: 11 | I29: Not given | J29: 1.8 | K29: Y | L29: 0.86 | M29: Urgent | N29: On Hold | O29: 12 | P29: =IF(global_freelancer_raw[[#This Row],[No of projects ]]<=5,"Entry level","Well Experienced") -> Well Experienced | Q29: 4
A30: FL250029 | B30: Megan Jones | C30: Female | D30: 47 | E30: Canada | F30: English | G30: AI | H30: 22 | I30: 30 | J30: 1.3 | K30: 0 | L30: 0.62 | M30: Urgent | N30: On Hold | O30: 14 | P30: =IF(global_freelancer_raw[[#This Row],[No of projects ]]<=5,"Entry level","Well Experienced") -> Well Experienced | Q30: 2
A31: FL250030 | B31: Lori Smith | C31: Female | D31: 41 | E31: Netherlands | F31: Dutch | G31: Data Analysis | H31: 14 | I31: USD 75 | J31: 1.2 | K31: 0 | L31: Not Mentioned | M31: Follow-up | N31: On Hold | O31: 6 | P31: =IF(global_freelancer_raw[[#This Row],[No of projects ]]<=5,"Entry level","Well Experienced") -> Well Experienced | Q31: 5
A32: FL250031 | B32: Eric Carpenter | C32: Male | D32: 22 | E32: Netherlands | F32: Dutch | G32: DevOps | H32: 4 | I32: Not given | J32: 1 | K32: yes | L32: Not Mentioned | M32: Follow-up | N32: Completed | O32: 3 | P32: =IF(global_freelancer_raw[[#This Row],[No of projects ]]<=5,"Entry level","Well Experienced") -> Entry level | Q32: 1
A33: FL250032 | B33: Timothy Daniels | C33: Male | D33: 38 | E33: France | F33: French | G33: Machine Learning | H33: 19 | I33: USD 100 | J33: 4.2 | K33: N | L33: 0.68 | M33: Reviewed | N33: Completed | O33: 10 | P33: =IF(global_freelancer_raw[[#This Row],[No of projects ]]<=5,"Entry level","Well Experienced") -> Well Experienced | Q33: 10
A34: FL250033 | B34: Robert Nelson | C34: Male | D34: 46 | E34: Egypt | F34: Arabic | G34: AI | H34: 9 | I34: 20 | J34: 1.4 | K34: TRUE | L34: 0.76 | M34: Follow-up | N34: Completed | O34: 13 | P34: =IF(global_freelancer_raw[[#This Row],[No of projects ]]<=5,"Entry level","Well Experienced") -> Well Experienced | Q34: 6
A35: FL250034 | B35: Michael Anderson | C35: Male | D35: Not given | E35: South Korea | F35: Korean | G35: AI | H35: 9 | I35: 40 | J35: 2.4 | K35: yes | L35: 82 | M35: Pending | N35: Inactive | O35: 15 | P35: =IF(global_freelancer_raw[[#This Row],[No of projects ]]<=5,"Entry level","Well Experienced") -> Well Experienced | Q35: 3
A36: FL250035 | B36: Jessica Snyder | C36: Female | D36: 54 | E36: US | F36: English | G36: Web Development | H36: 32 | I36: 75 | J36: 1 | K36: yes | L36: 0.81 | M36: Urgent | N36: Inactive | O36: 18 | P36: =IF(global_freelancer_raw[[#This Row],[No of projects ]]<=5,"Entry level","Well Experienced") -> Well Experienced | Q36: 10
A37: FL250036 | B37: Emily Daniels | C37: Female | D37: 52 | E37: South Korea | F37: Korean | G37: Not Mentioned | H37: 28 | I37: $20 | J37: Not Mentioned | K37: 0 | L37: Not Mentioned | M37: Urgent | N37: Inactive | O37: 18 | P37: =IF(global_freelancer_raw[[#This Row],[No of projects ]]<=5,"Entry level","Well Experienced") -> Well Experienced | Q37: 2
A38: FL250037 | B38: Jamie Ramirez | C38: Female | D38: 42 | E38: Japan | F38: Japanese | G38: Mobile Apps | H38: 6 | I38: 40 | J38: Not Mentioned | K38: 0 | L38: 0.63 | M38: Pending | N38: Inactive | O38: 15 | P38: =IF(global_freelancer_raw[[#This Row],[No of projects ]]<=5,"Entry level","Well Experienced") -> Well Experienced | Q38: 6
A39: FL250038 | B39: Amy Harrison | C39: Female | D39: 29 | E39: Netherlands | F39: Dutch | G39: Graphic Design | H39: 10 | I39: 40 | J39: 2.2 | K39: N | L39: 0.67 | M39: Follow-up | N39: On Hold | O39: 10 | P39: =IF(global_freelancer_raw[[#This Row],[No of projects ]]<=5,"Entry level","Well Experienced") -> Well Experienced | Q39: 9
A40: FL250039 | B40: Melinda White | C40: Female | D40: 42 | E40: South Africa | F40: Afrikaans | G40: Mobile Apps | H40: 23 | I40: 50 | J40: 3.2 | K40: yes | L40: Not Mentioned | M40: Pending | N40: On Hold | O40: 13 | P40: =IF(global_freelancer_raw[[#This Row],[No of projects ]]<=5,"Entry level","Well Experienced") -> Well Experienced | Q40: 3
...

Sheet Day 1 - Observation
A1: Observation
A2: 1 | B2: The dataset has 16 columns and 1000 rows
A3: 2 | B3: In this dataset a global freelancers who provides specialized services to clients worldwide on a project by project details are there.
A4: 3 | B4: And I have found some missing values and inconsistent data.
A5: 4 | B5: Here they are from 21 countries
A6: 5 | B6: I can see 10 different kinds of skills ,different years of experience,no of projects they have done.
A7: 6 | B7: Dataset holds numeric and non numeric data.
A8: 7 | B8: We need to structure the data for analysis so data cleaning is required before that.

Sheet Day 2-Data Entry & Formatting
A1: Data Entry & Formatting
A2: click here
A3: I have seen missing values in some columns and replaced by not mentioned and not given.
A4: Makes changes in the dataset in proper format:Bold,color and the alignment.
A5: Now the data looks clean and readable.

Sheet Day 3 – Basic Excel Formulas (P
A1: SUM(), AVERAGE(),MIN(), MAX(), COUNT() | B1: No of projects
A2: Total | B2: =SUM(global_freelancer_raw[[No of projects ]]) -> 8715
A3: Average | B3: =AVERAGE(global_freelancer_raw[[No of projects ]]) -> 8.715
A4: Min | B4: =MIN(global_freelancer_raw[[No of projects ]]) -> 1
A5: Max | B5: =MAX(global_freelancer_raw[[No of projects ]]) -> 20
A6: Count | B6: =COUNT(global_freelancer_raw[[No of projects ]]) -> 1000

Sheet Day 4 – Basic Excel Formulas (P
A1: IF(), SUMIF(), COUNTIF(), AVERAGEIF()
B2: No of projects of Data Analysis
A3: Sumif | B3: =SUMIF('global_freelancer Cleaned data'!G:G,"data analysis",'global_freelancer Cleaned data'!O:O) -> 810
B5: No of projects >10
A6: Countif | B6: =COUNTIF('global_freelancer Cleaned data'!O:O,">10") -> 404
B8: No of projects of AI
A9: Averageif | B9: =AVERAGEIF('global_freelancer Cleaned data'!G:G,"AI",'global_freelancer Cleaned data'!O:O) -> 7.96
A12: IF | B12: CLICK HERE

Sheet Day 5 – Text Functions
A1: Freelancer ID | B1: Name | C1: UPPER | D1: LOWER | E1: PROPER | F1: LEFT | G1: RIGHT | H1: MIDDLE
A2: FL250001 | B2: Ms. Nicole Kidd | C2: =UPPER(B2) -> MS. NICOLE KIDD | D2: =LOWER(B2) -> ms. nicole kidd | E2: =PROPER(C2) -> Ms. Nicole Kidd | F2: =LEFT(A2,2) -> FL | G2: =RIGHT(A2,2) -> 01 | H2: =MID(A2,3,4) -> 2500
A3: FL250002 | B3: Vanessa Garcia | C3: =UPPER(B3) -> VANESSA GARCIA | D3: =LOWER(B3) -> vanessa garcia | E3: =PROPER(C3) -> Vanessa Garcia | F3: =LEFT(A3,2) -> FL | G3: =RIGHT(A3,2) -> 02 | H3: =MID(A3,3,4) -> 2500
A4: FL250003 | B4: Juan Nelson | C4: =UPPER(B4) -> JUAN NELSON | D4: =LOWER(B4) -> juan nelson | E4: =PROPER(C4) -> Juan Nelson | F4: =LEFT(A4,2) -> FL | G4: =RIGHT(A4,2) -> 03 | H4: =MID(A4,3,4) -> 2500
A5: FL250004 | B5: Amanda Spencer | C5: =UPPER(B5) -> AMANDA SPENCER | D5: =LOWER(B5) -> amanda spencer | E5: =PROPER(C5) -> Amanda Spencer | F5: =LEFT(A5,2) -> FL | G5: =RIGHT(A5,2) -> 04 | H5: =MID(A5,3,4) -> 2500
A6: FL250005 | B6: Lynn Curtis DDS | C6: =UPPER(B6) -> LYNN CURTIS DDS | D6: =LOWER(B6) -> lynn curtis dds | E6: =PROPER(C6) -> Lynn Curtis Dds | F6: =LEFT(A6,2) -> FL | G6: =RIGHT(A6,2) -> 05 | H6: =MID(A6,3,4) -> 2500
A7: FL250006 | B7: Lisa Johnson | C7: =UPPER(B7) -> LISA JOHNSON | D7: =LOWER(B7) -> lisa johnson | E7: =PROPER(C7) -> Lisa Johnson | F7: =LEFT(A7,2) -> FL | G7: =RIGHT(A7,2) -> 06 | H7: =MID(A7,3,4) -> 2500
A8: FL250007 | B8: Eric Myers | C8: =UPPER(B8) -> ERIC MYERS | D8: =LOWER(B8) -> eric myers | E8: =PROPER(C8) -> Eric Myers | F8: =LEFT(A8,2) -> FL | G8: =RIGHT(A8,2) -> 07 | H8: =MID(A8,3,4) -> 2500 | K8: UPPER | L8: CLICK HERE
A9: FL250008 | B9: Ricky Graham | C9: =UPPER(B9) -> RICKY GRAHAM | D9: =LOWER(B9) -> ricky graham | E9: =PROPER(C9) -> Ricky Graham | F9: =LEFT(A9,2) -> FL | G9: =RIGHT(A9,2) -> 08 | H9: =MID(A9,3,4) -> 2500 | K9: LOWER | L9: CLICK HERE
A10: FL250009 | B10: Sean Martin | C10: =UPPER(B10) -> SEAN MARTIN | D10: =LOWER(B10) -> sean martin | E10: =PROPER(C10) -> Sean Martin | F10: =LEFT(A10,2) -> FL | G10: =RIGHT(A10,2) -> 09 | H10: =MID(A10,3,4) -> 2500 | K10: PROPER | L10: CLICK HERE
A11: FL250010 | B11: Matthew Lloyd | C11: =UPPER(B11) -> MATTHEW LLOYD | D11: =LOWER(B11) -> matthew lloyd | E11: =PROPER(C11) -> Matthew Lloyd | F11: =LEFT(A11,2) -> FL | G11: =RIGHT(A11,2) -> 10 | H11: =MID(A11,3,4) -> 2500 | K11: LEFT | L11: CLICK HERE
A12: FL250011 | B12: Gavin Randall | C12: =UPPER(B12) -> GAVIN RANDALL | D12: =LOWER(B12) -> gavin randall | E12: =PROPER(C12) -> Gavin Randall | F12: =LEFT(A12,2) -> FL | G12: =RIGHT(A12,2) -> 11 | H12: =MID(A12,3,4) -> 2500 | K12: RIGHT | L12: CLICK HERE
A13: FL250012 | B13: Michelle Curtis | C13: =UPPER(B13) -> MICHELLE CURTIS | D13: =LOWER(B13) -> michelle curtis | E13: =PROPER(C13) -> Michelle Curtis | F13: =LEFT(A13,2) -> FL | G13: =RIGHT(A13,2) -> 12 | H13: =MID(A13,3,4) -> 2500 | K13: MIDDLE | L13: CLICK HERE
A14: FL250013 | B14: Alice Schneider | C14: =UPPER(B14) -> ALICE SCHNEIDER | D14: =LOWER(B14) -> alice schneider | E14: =PROPER(C14) -> Alice Schneider | F14: =LEFT(A14,2) -> FL | G14: =RIGHT(A14,2) -> 13 | H14: =MID(A14,3,4) -> 2500
A15: FL250014 | B15: Phillip Shelton | C15: =UPPER(B15) -> PHILLIP SHELTON | D15: =LOWER(B15) -> phillip shelton | E15: =PROPER(C15) -> Phillip Shelton | F15: =LEFT(A15,2) -> FL | G15: =RIGHT(A15,2) -> 14 | H15: =MID(A15,3,4) -> 2500
A16: FL250015 | B16: Edward Ferguson | C16: =UPPER(B16) -> EDWARD FERGUSON | D16: =LOWER(B16) -> edward ferguson | E16: =PROPER(C16) -> Edward Ferguson | F16: =LEFT(A16,2) -> FL | G16: =RIGHT(A16,2) -> 15 | H16: =MID(A16,3,4) -> 2500
A17: FL250016 | B17: Wyatt Stout | C17: =UPPER(B17) -> WYATT STOUT | D17: =LOWER(B17) -> wyatt stout | E17: =PROPER(C17) -> Wyatt Stout | F17: =LEFT(A17,2) -> FL | G17: =RIGHT(A17,2) -> 16 | H17: =MID(A17,3,4) -> 2500
A18: FL250017 | B18: Laura Johnson | C18: =UPPER(B18) -> LAURA JOHNSON | D18: =LOWER(B18) -> laura johnson | E18: =PROPER(C18) -> Laura Johnson | F18: =LEFT(A18,2) -> FL | G18: =RIGHT(A18,2) -> 17 | H18: =MID(A18,3,4) -> 2500
A19: FL250018 | B19: Scott Burns | C19: =UPPER(B19) -> SCOTT BURNS | D19: =LOWER(B19) -> scott burns | E19: =PROPER(C19) -> Scott Burns | F19: =LEFT(A19,2) -> FL | G19: =RIGHT(A19,2) -> 18 | H19: =MID(A19,3,4) -> 2500
A20: FL250019 | B20: Tyler Aguirre | C20: =UPPER(B20) -> TYLER AGUIRRE | D20: =LOWER(B20) -> tyler aguirre | E20: =PROPER(C20) -> Tyler Aguirre | F20: =LEFT(A20,2) -> FL | G20: =RIGHT(A20,2) -> 19 | H20: =MID(A20,3,4) -> 2500
A21: FL250020 | B21: Matthew Lawson | C21: =UPPER(B21) -> MATTHEW LAWSON | D21: =LOWER(B21) -> matthew lawson | E21: =PROPER(C21) -> Matthew Lawson | F21: =LEFT(A21,2) -> FL | G21: =RIGHT(A21,2) -> 20 | H21: =MID(A21,3,4) -> 2500
A22: FL250021 | B22: James Cherry | C22: =UPPER(B22) -> JAMES CHERRY | D22: =LOWER(B22) -> james cherry | E22: =PROPER(C22) -> James Cherry | F22: =LEFT(A22,2) -> FL | G22: =RIGHT(A22,2) -> 21 | H22: =MID(A22,3,4) -> 2500
A23: FL250022 | B23: Samuel Sanford | C23: =UPPER(B23) -> SAMUEL SANFORD | D23: =LOWER(B23) -> samuel sanford | E23: =PROPER(C23) -> Samuel Sanford | F23: =LEFT(A23,2) -> FL | G23: =RIGHT(A23,2) -> 22 | H23: =MID(A23,3,4) -> 2500
A24: FL250023 | B24: Cesar Greene | C24: =UPPER(B24) -> CESAR GREENE | D24: =LOWER(B24) -> cesar greene | E24: =PROPER(C24) -> Cesar Greene | F24: =LEFT(A24,2) -> FL | G24: =RIGHT(A24,2) -> 23 | H24: =MID(A24,3,4) -> 2500
A25: FL250024 | B25: Melanie Carter | C25: =UPPER(B25) -> MELANIE CARTER | D25: =LOWER(B25) -> melanie carter | E25: =PROPER(C25) -> Melanie Carter | F25: =LEFT(A25,2) -> FL | G25: =RIGHT(A25,2) -> 24 | H25: =MID(A25,3,4) -> 2500
... A1001: FL251000 | B1001: Dawn Green | C1001: =UPPER(B1001) -> DAWN GREEN | D1001: =LOWER(B1001) -> dawn green | E1001: =PROPER(C1001) -> Dawn Green | F1001: =LEFT(A1001,2) -> FL | G1001: =RIGHT(A1001,2) -> 00 | H1001: =MID(A1001,3,4) -> 2510

Sheet Day 6 – Data Validation & Clean
A1: freelancer_ID | B1: name | C1: gender | D1: Gender_ | E1: age | F1: Age_ | G1: country | H1: Country_ | I1: primary_skill | J1: Primary_skill_ | K1: years_of_experience | L1: Years_of_Experience_ | M1: hourly_rate (USD) | N1: Hourly_rate (USD)_ | O1: rating | P1: Rating_ | Q1: is_active | R1: Is_active_ | S1: client_satisfaction | T1: Client Satisfaction_
A2: FL250001 | B2: Ms. Nicole Kidd | C2: f | D2: Female | E2: 52 | F2: 52 | G2: Italy | H2: Italy | I2: Blockchain Development | J2: Blockchain Development | K2: 11 | L2: 11 | M2: 100 | N2: 100 | P2: Not Mentioned | Q2: 0 | R2: 0 | T2: Not Mentioned
A3: FL250002 | B3: Vanessa Garcia | C3: FEMALE | D3: Female | E3: 52 | F3: 52 | G3: Australia | H3: Australia | I3: Mobile Apps | J3: Mobile Apps | K3: 34 | L3: 34 | M3: USD 100 | N3: USD 100 | O3: 3.3 | P3: 3.3 | Q3: 1 | R3: 1 | S3: 0.84 | T3: 0.84
A4: FL250003 | B4: Juan Nelson | C4: male | D4: Male | E4: 53 | F4: 53 | G4: Germany | H4: Germany | I4: Graphic Design | J4: Graphic Design | K4: 31 | L4: 31 | M4: 50 | N4: 50 | O4: 0 | P4: 0 | Q4: N | R4: N | S4: 0.71 | T4: 0.71
A5: FL250004 | B5: Amanda Spencer | C5: F | D5: Female | E5: 38 | F5: 38 | G5: Australia | H5: Australia | I5: Web Development | J5: Web Development | K5: 4 | L5: 4 | M5: $40 | N5: $40 | O5: 1.5 | P5: 1.5 | Q5: N | R5: N | S5: 0.9 | T5: 0.9
A6: FL250005 | B6: Lynn Curtis DDS | C6: female | D6: Female | E6: 53 | F6: 53 | G6: Germany | H6: Germany | J6: Not Mentioned | K6: 27 | L6: 27 | M6: 30 | N6: 30 | O6: 4.8 | P6: 4.8 | Q6: 0 | R6: 0 | S6: 0.83 | T6: 0.83
A7: FL250006 | B7: Lisa Johnson | C7: female | D7: Female | E7: 59 | F7: 59 | G7: Netherlands | H7: Netherlands | I7: AI | J7: AI | K7: 14 | L7: 14 | M7: $30 | N7: $30 | O7: 2.4 | P7: 2.4 | Q7: FALSE | R7: FALSE | T7: Not Mentioned
A8: FL250007 | B8: Eric Myers | C8: m | D8: Male | E8: 52 | F8: 52 | G8: Indonesia | H8: Indonesia | I8: Data Analysis | J8: Data Analysis | K8: 10 | L8: 10 | M8: USD 75 | N8: USD 75 | O8: 3.1 | P8: 3.1 | Q8: 0 | R8: 0 | S8: 0.94 | T8: 0.94
A9: FL250008 | B9: Ricky Graham | C9: male | D9: Male | E9: 43 | F9: 43 | G9: Italy | H9: Italy | I9: Blockchain Development | J9: Blockchain Development | K9: 14 | L9: 14 | M9: USD 40 | N9: USD 40 | O9: 4.6 | P9: 4.6 | Q9: FALSE | R9: FALSE | S9: 0.94 | T9: 0.94
A10: FL250009 | B10: Sean Martin | C10: male | D10: Male | E10: 26 | F10: 26 | G10: US | H10: US | I10: Blockchain Development | J10: Blockchain Development | K10: 4 | L10: 4 | N10: Not given | O10: 4 | P10: 4 | Q10: TRUE | R10: TRUE | S10: 0.76 | T10: 0.76
A11: FL250010 | B11: Matthew Lloyd | C11: MALE | D11: Male | E11: 52 | F11: 52 | G11: Turkey | H11: Turkey | I11: AI | J11: AI | K11: 22 | L11: 22 | M11: $50 | N11: $50 | P11: Not Mentioned | Q11: 1 | R11: 1 | T11: Not Mentioned
A12: FL250011 | B12: Gavin Randall | C12: m | D12: Male | E12: 40 | F12: 40 | G12: UK | H12: UK | I12: Data Analysis | J12: Data Analysis | K12: 17 | L12: 17 | M12: 40 | N12: 40 | O12: 3.6 | P12: 3.6 | Q12: yes | R12: yes | S12: 0.77 | T12: 0.77
A13: FL250012 | B13: Michelle Curtis | C13: FEMALE | D13: Female | E13: 55 | F13: 55 | G13: Argentina | H13: Argentina | I13: UI/UX Design | J13: UI/UX Design | K13: 15 | L13: 15 | N13: Not given | P13: Not Mentioned | Q13: Y | R13: Y | S13: 0.86 | T13: 0.86
A14: FL250013 | B14: Alice Schneider | C14: Female | D14: Female | E14: 57 | F14: 57 | G14: UK | H14: UK | I14: Cybersecurity | J14: Cybersecurity | K14: 18 | L14: 18 | N14: Not given | O14: 2 | P14: 2 | Q14: 0 | R14: 0 | S14: 0.86 | T14: 0.86
A15: FL250014 | B15: Phillip Shelton | C15: MALE | D15: Male | E15: 38 | F15: 38 | H15: Not Mentioned | I15: Graphic Design | J15: Graphic Design | K15: 20 | L15: 20 | M15: USD 75 | N15: USD 75 | O15: 2.9 | P15: 2.9 | Q15: 1 | R15: 1 | S15: 0.93 | T15: 0.93
A16: FL250015 | B16: Edward Ferguson | C16: MALE | D16: Male | E16: 50 | F16: 50 | G16: Germany | H16: Germany | I16: Data Analysis | J16: Data Analysis | K16: 22 | L16: 22 | M16: 75 | N16: 75 | O16: 3.7 | P16: 3.7 | Q16: 1 | R16: 1 | S16: 0.7 | T16: 0.7
A17: FL250016 | B17: Wyatt Stout | C17: m | D17: Male | E17: 42 | F17: 42 | G17: Japan | H17: Japan | J17: Not Mentioned | K17: 0 | L17: 0 | M17: $30 | N17: $30 | O17: 1.2 | P17: 1.2 | Q17: 0 | R17: 0 | S17: 0.69 | T17: 0.69
A18: FL250017 | B18: Laura Johnson | C18: Female | D18: Female | E18: 39 | F18: 39 | G18: Australia | H18: Australia | I18: DevOps | J18: DevOps | K18: 13 | L18: 13 | M18: $30 | N18: $30 | O18: 2.5 | P18: 2.5 | Q18: FALSE | R18: FALSE | S18: 0.6 | T18: 0.6
A19: FL250018 | B19: Scott Burns | C19: M | D19: Male | E19: 56 | F19: 56 | G19: India | H19: India | I19: Blockchain Development | J19: Blockchain Development | L19: Not Mentioned | N19: Not given | P19: Not Mentioned | R19: Not Mentioned | S19: 0.87 | T19: 0.87
A20: FL250019 | B20: Tyler Aguirre | C20: Male | D20: Male | E20: 56 | F20: 56 | G20: US | H20: US | I20: UI/UX Design | J20: UI/UX Design | K20: 31 | L20: 31 | M20: USD 50 | N20: USD 50 | O20: 1.1 | P20: 1.1 | Q20: N | R20: N | S20: 0.75 | T20: 0.75
A21: FL250020 | B21: Matthew Lawson | C21: Male | D21: Male | E21: 57 | F21: 57 | G21: Italy | H21: Italy | I21: Web Development | J21: Web Development | K21: 3 | L21: 3 | M21: USD 100 | N21: USD 100 | O21: 1.8 | P21: 1.8 | Q21: yes | R21: yes | S21: 0.68 | T21: 0.68
A22: FL250021 | B22: James Cherry | C22: Male | D22: Male | F22: Not given | G22: Indonesia | H22: Indonesia | I22: AI | J22: AI | K22: 9 | L22: 9 | M22: 50 | N22: 50 | O22: 1.8 | P22: 1.8 | Q22: FALSE | R22: FALSE | S22: 0.65 | T22: 0.65
A23: FL250022 | B23: Samuel Sanford | C23: m | D23: Male | E23: 51 | F23: 51 | G23: Japan | H23: Japan | I23: DevOps | J23: DevOps | L23: Not Mentioned | N23: Not given | O23: 2.4 | P23: 2.4 | Q23: N | R23: N | S23: 0.69 | T23: 0.69
A24: FL250023 | B24: Cesar Greene | C24: m | D24: Male | E24: 51 | F24: 51 | G24: Brazil | H24: Brazil | I24: Cybersecurity | J24: Cybersecurity | K24: 21 | L24: 21 | M24: USD 30 | N24: USD 30 | O24: 4.7 | P24: 4.7 | Q24: N | R24: N | T24: Not Mentioned
A25: FL250024 | B25: Melanie Carter | C25: female | D25: Female | E25: 51 | F25: 51 | G25: South Korea | H25: South Korea | I25: Machine Learning | J25: Machine Learning | K25: 15 | L25: 15 | M25: $50 | N25: $50 | O25: 1.3 | P25: 1.3 | Q25: 1 | R25: 1 | S25: 1 | T25: 1
A26: FL250025 | B26: Jennifer Martin | C26: f | D26: Female | E26: 54 | F26: 54 | G26: Indonesia | H26: Indonesia | I26: Machine Learning | J26: Machine Learning | K26: 13 | L26: 13 | M26: 75 | N26: 75 | O26: 2.9 | P26: 2.9 | R26: Not Mentioned | S26: 92 | T26: 92
A27: FL250026 | B27: Anna Mccann | C27: FEMALE | D27: Female | E27: 22 | F27: 22 | G27: South Korea | H27: South Korea | I27: DevOps | J27: DevOps | K27: 0 | L27: 0 | M27: USD 30 | N27: USD 30 | O27: 1.2 | P27: 1.2 | Q27: 1 | R27: 1 | S27: 0.7 | T27: 0.7
A28: FL250027 | B28: Marissa Bass | C28: female | D28: Female | E28: 34 | F28: 34 | G28: Japan | H28: Japan | I28: Blockchain Development | J28: Blockchain Development | K28: 8 | L28: 8 | M28: $20 | N28: $20 | O28: 0 | P28: 0 | Q28: TRUE | R28: TRUE | S28: 0.89 | T28: 0.89
A29: FL250028 | B29: Alexis Day | C29: Female | D29: Female | E29: 36 | F29: 36 | G29: Russia | H29: Russia | I29: Graphic Design | J29: Graphic Design | K29: 11 | L29: 11 | N29: Not given | O29: 1.8 | P29: 1.8 | Q29: Y | R29: Y | S29: 0.86 | T29: 0.86
A30: FL250029 | B30: Megan Jones | C30: female | D30: Female | E30: 47 | F30: 47 | G30: Canada | H30: Canada | I30: AI | J30: AI | K30: 22 | L30: 22 | M30: 30 | N30: 30 | O30: 1.3 | P30: 1.3 | Q30: 0 | R30: 0 | S30: 0.62 | T30: 0.62
A31: FL250030 | B31: Lori Smith | C31: FEMALE | D31: Female | E31: 41 | F31: 41 | G31: Netherlands | H31: Netherlands | I31: Data Analysis | J31: Data Analysis | K31: 14 | L31: 14 | M31: USD 75 | N31: USD 75 | O31: 1.2 | P31: 1.2 | Q31: 0 | R31: 0 | T31: Not Mentioned
A32: FL250031 | B32: Eric Carpenter | C32: Male | D32: Male | E32: 22 | F32: 22 | G32: Netherlands | H32: Netherlands | I32: DevOps | J32: DevOps | K32: 4 | L32: 4 | N32: Not given | O32: 1 | P32: 1 | Q32: yes | R32: yes | T32: Not Mentioned
A33: FL250032 | B33: Timothy Daniels | C33: Male | D33: Male | E33: 38 | F33: 38 | G33: France | H33: France | I33: Machine Learning | J33: Machine Learning | K33: 19 | L33: 19 | M33: USD 100 | N33: USD 100 | O33: 4.2 | P33: 4.2 | Q33: N | R33: N | S33: 0.68 | T33: 0.68
A34: FL250033 | B34: Robert Nelson | C34: M | D34: Male | E34: 46 | F34: 46 | G34: Egypt | H34: Egypt | I34: AI | J34: AI | K34: 9 | L34: 9 | M34: 20 | N34: 20 | O34: 1.4 | P34: 1.4 | Q34: TRUE | R34: TRUE | S34: 0.76 | T34: 0.76
A35: FL250034 | B35: Michael Anderson | C35: male | D35: Male | F35: Not given | G35: South Korea | H35: South Korea | I35: AI | J35: AI | K35: 9 | L35: 9 | M35: 40 | N35: 40 | O35: 2.4 | P35: 2.4 | Q35: yes | R35: yes | S35: 82 | T35: 82
A36: FL250035 | B36: Jessica Snyder | C36: FEMALE | D36: Female | E36: 54 | F36: 54 | G36: US | H36: US | I36: Web Development | J36: Web Development | K36: 32 | L36: 32 | M36: 75 | N36: 75 | O36: 1 | P36: 1 | Q36: yes | R36: yes | S36: 0.81 | T36: 0.81
A37: FL250036 | B37: Emily Daniels | C37: female | D37: Female | E37: 52 | F37: 52 | G37: South Korea | H37: South Korea | J37: Not Mentioned | K37: 28 | L37: 28 | M37: $20 | N37: $20 | P37: Not Mentioned | Q37: 0 | R37: 0 | T37: Not Mentioned
A38: FL250037 | B38: Jamie Ramirez | C38: f | D38: Female | E38: 42 | F38: 42 | G38: Japan | H38: Japan | I38: Mobile Apps | J38: Mobile Apps | K38: 6 | L38: 6 | M38: 40 | N38: 40 | P38: Not Mentioned | Q38: 0 | R38: 0 | S38: 0.63 | T38: 0.63
A39: FL250038 | B39: Amy Harrison | C39: F | D39: Female | E39: 29 | F39: 29 | G39: Netherlands | H39: Netherlands | I39: Graphic Design | J39: Graphic Design | K39: 10 | L39: 10 | M39: 40 | N39: 40 | O39: 2.2 | P39: 2.2 | Q39: N | R39: N | S39: 0.67 | T39: 0.67
A40: FL250039 | B40: Melinda White | C40: F | D40: Female | E40: 42 | F40: 42 | G40: South Africa | H40: South Africa | I40: Mobile Apps | J40: Mobile Apps | K40: 23 | L40: 23 | M40: 50 | N40: 50 | O40: 3.2 | P40: 3.2 | Q40: yes | R40: yes | T40: Not Mentioned
...

Sheet Day 7 –Power Query cleaned data
A1: Freelancer ID | B1: Name | C1: Gender | D1: Age | E1: Country | F1: Language | G1: Primary_skill | H1: Years_of_Experience | I1: Hourly_rate (USD) | J1: Rating | K1: Is_active | L1: Client Satisfaction | M1: Notes | N1: Status | O1: No of projects | P1: IF Condition | Q1: Duration Months
A2: FL250001 | B2: Ms. Nicole Kidd | C2: Female | D2: 52 | E2: Italy | F2: Italian | G2: Blockchain Development | H2: 11 | I2: 100 | J2: Not Mentioned | K2: 0 | L2: Not Mentioned | M2: Reviewed | N2: On Hold | O2: 13 | P2: =IF(global_freelancer_raw5[[#This Row],[No of projects ]]<=5,"Entry level","Well Experienced") -> Well Experienced | Q2: 6
A3: FL250002 | B3: Vanessa Garcia | C3: Female | D3: 52 | E3: Australia | F3: English | G3: Mobile Apps | H3: 34 | I3: USD 100 | J3: 3.3 | K3: 1 | L3: 0.84 | M3: Reviewed | N3: Completed | O3: 10 | P3: =IF(global_freelancer_raw5[[#This Row],[No of projects ]]<=5,"Entry level","Well Experienced") -> Well Experienced | Q3: 7
A4: FL250003 | B4: Juan Nelson | C4: Male | D4: 53 | E4: Germany | F4: Germany | G4: Graphic Design | H4: 31 | I4: 50 | J4: 0 | K4: N | L4: 0.71 | M4: Reviewed | N4: Active | O4: 16 | P4: =IF(global_freelancer_raw5[[#This Row],[No of projects ]]<=5,"Entry level","Well Experienced") -> Well Experienced | Q4: 16
A5: FL250004 | B5: Amanda Spencer | C5: Female | D5: 38 | E5: Australia | F5: English | G5: Web Development | H5: 4 | I5: $40 | J5: 1.5 | K5: N | L5: 0.9 | M5: Reviewed | N5: Completed | O5: 5 | P5: =IF(global_freelancer_raw5[[#This Row],[No of projects ]]<=5,"Entry level","Well Experienced") -> Entry level | Q5: 1
A6: FL250005 | B6: Lynn Curtis DDS | C6: Female | D6: 53 | E6: Germany | F6: Germany | G6: Not Mentioned | H6: 27 | I6: 30 | J6: 4.8 | K6: 0 | L6: 0.83 | M6: Reviewed | N6: On Hold | O6: 13 | P6: =IF(global_freelancer_raw5[[#This Row],[No of projects ]]<=5,"Entry level","Well Experienced") -> Well Experienced | Q6: 3
A7: FL250006 | B7: Lisa Johnson | C7: Female | D7: 59 | E7: Netherlands | F7: Dutch | G7: AI | H7: 14 | I7: $30 | J7: 2.4 | K7: FALSE | L7: Not Mentioned | M7: Urgent | N7: Active | O7: 8 | P7: =IF(global_freelancer_raw5[[#This Row],[No of projects ]]<=5,"Entry level","Well Experienced") -> Well Experienced | Q7: 3
A8: FL250007 | B8: Eric Myers | C8: Male | D8: 52 | E8: Indonesia | F8: Indonesian | G8: Data Analysis | H8: 10 | I8: USD 75 | J8: 3.1 | K8: 0 | L8: 0.94 | M8: Reviewed | N8: On Hold | O8: 10 | P8: =IF(global_freelancer_raw5[[#This Row],[No of projects ]]<=5,"Entry level","Well Experienced") -> Well Experienced | Q8: 3
A9: FL250008 | B9: Ricky Graham | C9: Male | D9: 43 | E9: Italy | F9: Italian | G9: Blockchain Development | H9: 14 | I9: USD 40 | J9: 4.6 | K9: FALSE | L9: 0.94 | M9: Urgent | N9: On Hold | O9: 7 | P9: =IF(global_freelancer_raw5[[#This Row],[No of projects ]]<=5,"Entry level","Well Experienced") -> Well Experienced | Q9: 10
A10: FL250009 | B10: Sean Martin | C10: Male | D10: 26 | E10: US | F10: English | G10: Blockchain Development | H10: 4 | I10: Not given | J10: 4 | K10: TRUE | L10: 0.76 | M10: Reviewed | N10: Inactive | O10: 2 | P10: =IF(global_freelancer_raw5[[#This Row],[No of projects ]]<=5,"Entry level","Well Experienced") -> Entry level | Q10: 4
A11: FL250010 | B11: Matthew Lloyd | C11: Male | D11: 52 | E11: Turkey | F11: Turkish | G11: AI | H11: 22 | I11: $50 | J11: Not Mentioned | K11: 1 | L11: Not Mentioned | M11: Pending | N11: Active | O11: 16 | P11: =IF(global_freelancer_raw5[[#This Row],[No of projects ]]<=5,"Entry level","Well Experienced") -> Well Experienced | Q11: 5
A12: FL250011 | B12: Gavin Randall | C12: Male | D12: 40 | E12: UK | F12: English | G12: Data Analysis | H12: 17 | I12: 40 | J12: 3.6 | K12: yes | L12: 0.77 | M12: Follow-up | N12: Inactive | O12: 20 | P12: =IF(global_freelancer_raw5[[#This Row],[No of projects ]]<=5,"Entry level","Well Experienced") -> Well Experienced | Q12: 5
A13: FL250012 | B13: Michelle Curtis | C13: Female | D13: 55 | E13: Argentina | F13: Spanish | G13: UI/UX Design | H13: 15 | I13: Not given | J13: Not Mentioned | K13: Y | L13: 0.86 | M13: Urgent | N13: Active | O13: 13 | P13: =IF(global_freelancer_raw5[[#This Row],[No of projects ]]<=5,"Entry level","Well Experienced") -> Well Experienced | Q13: 4
A14: FL250013 | B14: Alice Schneider | C14: Female | D14: 57 | E14: UK | F14: English | G14: Cybersecurity | H14: 18 | I14: Not given | J14: 2 | K14: 0 | L14: 0.86 | M14: Reviewed | N14: On Hold | O14: 16 | P14: =IF(global_freelancer_raw5[[#This Row],[No of projects ]]<=5,"Entry level","Well Experienced") -> Well Experienced | Q14: 15
A15: FL250014 | B15: Phillip Shelton | C15: Male | D15: 38 | E15: Not Mentioned | F15: Spanish | G15: Graphic Design | H15: 20 | I15: USD 75 | J15: 2.9 | K15: 1 | L15: 0.93 | M15: Pending | N15: On Hold | O15: 17 | P15: =IF(global_freelancer_raw5[[#This Row],[No of projects ]]<=5,"Entry level","Well Experienced") -> Well Experienced | Q15: 12
A16: FL250015 | B16: Edward Ferguson | C16: Male | D16: 50 | E16: Germany | F16: Germany | G16: Data Analysis | H16: 22 | I16: 75 | J16: 3.7 | K16: 1 | L16: 0.7 | M16: Follow-up | N16: Completed | O16: 14 | P16: =IF(global_freelancer_raw5[[#This Row],[No of projects ]]<=5,"Entry level","Well Experienced") -> Well Experienced | Q16: 6
A17: FL250016 | B17: Wyatt Stout | C17: Male | D17: 42 | E17: Japan | F17: Japanese | G17: Not Mentioned | H17: 0 | I17: $30 | J17: 1.2 | K17: 0 | L17: 0.69 | M17: Urgent | N17: Active | O17: 5 | P17: =IF(global_freelancer_raw5[[#This Row],[No of projects ]]<=5,"Entry level","Well Experienced") -> Entry level | Q17: 2
A18: FL250017 | B18: Laura Johnson | C18: Female | D18: 39 | E18: Australia | F18: English | G18: DevOps | H18: 13 | I18: $30 | J18: 2.5 | K18: FALSE | L18: 0.6 | M18: Follow-up | N18: Inactive | O18: 7 | P18: =IF(global_freelancer_raw5[[#This Row],[No of projects ]]<=5,"Entry level","Well Experienced") -> Well Experienced | Q18: 1
A19: FL250018 | B19: Scott Burns | C19: Male | D19: 56 | E19: India | F19: Hindi | G19: Blockchain Development | H19: Not Mentioned | I19: Not given | J19: Not Mentioned | K19: Not Mentioned | L19: 0.87 | M19: Pending | N19: Completed | O19: 1 | P19: =IF(global_freelancer_raw5[[#This Row],[No of projects ]]<=5,"Entry level","Well Experienced") -> Entry level | Q19: 2
A20: FL250019 | B20: Tyler Aguirre | C20: Male | D20: 56 | E20: US | F20: English | G20: UI/UX Design | H20: 31 | I20: USD 50 | J20: 1.1 | K20: N | L20: 0.75 | M20: Urgent | N20: Completed | O20: 13 | P20: =IF(global_freelancer_raw5[[#This Row],[No of projects ]]<=5,"Entry level","Well Experienced") -> Well Experienced | Q20: 3
A21: FL250020 | B21: Matthew Lawson | C21: Male | D21: 57 | E21: Italy | F21: Italian | G21: Web Development | H21: 3 | I21: USD 100 | J21: 1.8 | K21: yes | L21: 0.68 | M21: Follow-up | N21: Completed | O21: 1 | P21: =IF(global_freelancer_raw5[[#This Row],[No of projects ]]<=5,"Entry level","Well Experienced") -> Entry level | Q21: 1
A22: FL250021 | B22: James Cherry | C22: Male | D22: Not given | E22: Indonesia | F22: Indonesian | G22: AI | H22: 9 | I22: 50 | J22: 1.8 | K22: FALSE | L22: 0.65 | M22: Reviewed | N22: Inactive | O22: 15 | P22: =IF(global_freelancer_raw5[[#This Row],[No of projects ]]<=5,"Entry level","Well Experienced") -> Well Experienced | Q22: 6
A23: FL250022 | B23: Samuel Sanford | C23: Male | D23: 51 | E23: Japan | F23: Japanese | G23: DevOps | H23: Not Mentioned | I23: Not given | J23: 2.4 | K23: N | L23: 0.69 | M23: Urgent | N23: Completed | O23: 3 | P23: =IF(global_freelancer_raw5[[#This Row],[No of projects ]]<=5,"Entry level","Well Experienced") -> Entry level | Q23: 5
A24: FL250023 | B24: Cesar Greene | C24: Male | D24: 51 | E24: Brazil | F24: Portuguese | G24: Cybersecurity | H24: 21 | I24: USD 30 | J24: 4.7 | K24: N | L24: Not Mentioned | M24: Follow-up | N24: Inactive | O24: 14 | P24: =IF(global_freelancer_raw5[[#This Row],[No of projects ]]<=5,"Entry level","Well Experienced") -> Well Experienced | Q24: 2
A25: FL250024 | B25: Melanie Carter | C25: Female | D25: 51 | E25: South Korea | F25: Korean | G25: Machine Learning | H25: 15 | I25: $50 | J25: 1.3 | K25: 1 | L25: 1 | M25: Pending | N25: Completed | O25: 9 | P25: =IF(global_freelancer_raw5[[#This Row],[No of projects ]]<=5,"Entry level","Well Experienced") -> Well Experienced | Q25: 3
A26: FL250025 | B26: Jennifer Martin | C26: Female | D26: 54 | E26: Indonesia | F26: Indonesian | G26: Machine Learning | H26: 13 | I26: 75 | J26: 2.9 | K26: Not Mentioned | L26: 92 | M26: Pending | N26: Inactive | O26: 15 | P26: =IF(global_freelancer_raw5[[#This Row],[No of projects ]]<=5,"Entry level","Well Experienced") -> Well Experienced | Q26: 3
A27: FL250026 | B27: Anna Mccann | C27: Female | D27: 22 | E27: South Korea | F27: Korean | G27: DevOps | H27: 0 | I27: USD 30 | J27: 1.2 | K27: 1 | L27: 0.7 | M27: Urgent | N27: On Hold | O27: 5 | P27: =IF(global_freelancer_raw5[[#This Row],[No of projects ]]<=5,"Entry level","Well Experienced") -> Entry level | Q27: 2
A28: FL250027 | B28: Marissa Bass | C28: Female | D28: 34 | E28: Japan | F28: Japanese | G28: Blockchain Development | H28: 8 | I28: $20 | J28: 0 | K28: TRUE | L28: 0.89 | M28: Follow-up | N28: On Hold | O28: 6 | P28: =IF(global_freelancer_raw5[[#This Row],[No of projects ]]<=5,"Entry level","Well Experienced") -> Well Experienced | Q28: 1
A29: FL250028 | B29: Alexis Day | C29: Female | D29: 36 | E29: Russia | F29: Russian | G29: Graphic Design | H29: 11 | I29: Not given | J29: 1.8 | K29: Y | L29: 0.86 | M29: Urgent | N29: On Hold | O29: 12 | P29: =IF(global_freelancer_raw5[[#This Row],[No of projects ]]<=5,"Entry level","Well Experienced") -> Well Experienced | Q29: 4
A30: FL250029 | B30: Megan Jones | C30: Female | D30: 47 | E30: Canada | F30: English | G30: AI | H30: 22 | I30: 30 | J30: 1.3 | K30: 0 | L30: 0.62 | M30: Urgent | N30: On Hold | O30: 14 | P30: =IF(global_freelancer_raw5[[#This Row],[No of projects ]]<=5,"Entry level","Well Experienced") -> Well Experienced | Q30: 2
A31: FL250030 | B31: Lori Smith | C31: Female | D31: 41 | E31: Netherlands | F31: Dutch | G31: Data Analysis | H31: 14 | I31: USD 75 | J31: 1.2 | K31: 0 | L31: Not Mentioned | M31: Follow-up | N31: On Hold | O31: 6 | P31: =IF(global_freelancer_raw5[[#This Row],[No of projects ]]<=5,"Entry level","Well Experienced") -> Well Experienced | Q31: 5
A32: FL250031 | B32: Eric Carpenter | C32: Male | D32: 22 | E32: Netherlands | F32: Dutch | G32: DevOps | H32: 4 | I32: Not given | J32: 1 | K32: yes | L32: Not Mentioned | M32: Follow-up | N32: Completed | O32: 3 | P32: =IF(global_freelancer_raw5[[#This Row],[No of projects ]]<=5,"Entry level","Well Experienced") -> Entry level | Q32: 1
A33: FL250032 | B33: Timothy Daniels | C33: Male | D33: 38 | E33: France | F33: French | G33: Machine Learning | H33: 19 | I33: USD 100 | J33: 4.2 | K33: N | L33: 0.68 | M33: Reviewed | N33: Completed | O33: 10 | P33: =IF(global_freelancer_raw5[[#This Row],[No of projects ]]<=5,"Entry level","Well Experienced") -> Well Experienced | Q33: 10
A34: FL250033 | B34: Robert Nelson | C34: Male | D34: 46 | E34: Egypt | F34: Arabic | G34: AI | H34: 9 | I34: 20 | J34: 1.4 | K34: TRUE | L34: 0.76 | M34: Follow-up | N34: Completed | O34: 13 | P34: =IF(global_freelancer_raw5[[#This Row],[No of projects ]]<=5,"Entry level","Well Experienced") -> Well Experienced | Q34: 6
A35: FL250034 | B35: Michael Anderson | C35: Male | D35: Not given | E35: South Korea | F35: Korean | G35: AI | H35: 9 | I35: 40 | J35: 2.4 | K35: yes | L35: 82 | M35: Pending | N35: Inactive | O35: 15 | P35: =IF(global_freelancer_raw5[[#This Row],[No of projects ]]<=5,"Entry level","Well Experienced") -> Well Experienced | Q35: 3
A36: FL250035 | B36: Jessica Snyder | C36: Female | D36: 54 | E36: US | F36: English | G36: Web Development | H36: 32 | I36: 75 | J36: 1 | K36: yes | L36: 0.81 | M36: Urgent | N36: Inactive | O36: 18 | P36: =IF(global_freelancer_raw5[[#This Row],[No of projects ]]<=5,"Entry level","Well Experienced") -> Well Experienced | Q36: 10
A37: FL250036 | B37: Emily Daniels | C37: Female | D37: 52 | E37: South Korea | F37: Korean | G37: Not Mentioned | H37: 28 | I37: $20 | J37: Not Mentioned | K37: 0 | L37: Not Mentioned | M37: Urgent | N37: Inactive | O37: 18 | P37: =IF(global_freelancer_raw5[[#This Row],[No of projects ]]<=5,"Entry level","Well Experienced") -> Well Experienced | Q37: 2
A38: FL250037 | B38: Jamie Ramirez | C38: Female | D38: 42 | E38: Japan | F38: Japanese | G38: Mobile Apps | H38: 6 | I38: 40 | J38: Not Mentioned | K38: 0 | L38: 0.63 | M38: Pending | N38: Inactive | O38: 15 | P38: =IF(global_freelancer_raw5[[#This Row],[No of projects ]]<=5,"Entry level","Well Experienced") -> Well Experienced | Q38: 6
A39: FL250038 | B39: Amy Harrison | C39: Female | D39: 29 | E39: Netherlands | F39: Dutch | G39: Graphic Design | H39: 10 | I39: 40 | J39: 2.2 | K39: N | L39: 0.67 | M39: Follow-up | N39: On Hold | O39: 10 | P39: =IF(global_freelancer_raw5[[#This Row],[No of projects ]]<=5,"Entry level","Well Experienced") -> Well Experienced | Q39: 9
A40: FL250039 | B40: Melinda White | C40: Female | D40: 42 | E40: South Africa | F40: Afrikaans | G40: Mobile Apps | H40: 23 | I40: 50 | J40: 3.2 | K40: yes | L40: Not Mentioned | M40: Pending | N40: On Hold | O40: 13 | P40: =IF(global_freelancer_raw5[[#This Row],[No of projects ]]<=5,"Entry level","Well Experienced") -> Well Experienced | Q40: 3
...

Sheet Day 8–Handling Inconsistent Dat
B1: Text to Column | D1: Flashfill | E1: TRIM
A2: Freelancer ID | B2: Freelancer | C2: ID | D2: FreelancerID | E2: left | F2: Mid | G2: Right
A3: FL250001 | B3: FL | C3: 250001 | D3: FL250001 | E3: =LEFT(D3,3) -> FL2 | F3: =MID(D3,4,2) -> 50 | G3: =RIGHT(D3,3) -> 001
A4: FL250002 | B4: FL | C4: 250002 | D4: FL250002 | E4: =LEFT(D4,3) -> FL2 | F4: =MID(D4,4,2) -> 50 | G4: =RIGHT(D4,3) -> 002
A5: FL250003 | B5: FL | C5: 250003 | D5: FL250003 | E5: =LEFT(D5,3) -> FL2 | F5: =MID(D5,4,2) -> 50 | G5: =RIGHT(D5,3) -> 003
A6: FL250004 | B6: FL | C6: 250004 | D6: FL250004 | E6: =LEFT(D6,3) -> FL2 | F6: =MID(D6,4,2) -> 50 | G6: =RIGHT(D6,3) -> 004
A7: FL250005 | B7: FL | C7: 250005 | D7: FL250005 | E7: =LEFT(D7,3) -> FL2 | F7: =MID(D7,4,2) -> 50 | G7: =RIGHT(D7,3) -> 005
A8: FL250006 | B8: FL | C8: 250006 | D8: FL250006 | E8: =LEFT(D8,3) -> FL2 | F8: =MID(D8,4,2) -> 50 | G8: =RIGHT(D8,3) -> 006
A9: FL250007 | B9: FL | C9: 250007 | D9: FL250007 | E9: =LEFT(D9,3) -> FL2 | F9: =MID(D9,4,2) -> 50 | G9: =RIGHT(D9,3) -> 007
A10: FL250008 | B10: FL | C10: 250008 | D10: FL250008 | E10: =LEFT(D10,3) -> FL2 | F10: =MID(D10,4,2) -> 50 | G10: =RIGHT(D10,3) -> 008
A11: FL250009 | B11: FL | C11: 250009 | D11: FL250009 | E11: =LEFT(D11,3) -> FL2 | F11: =MID(D11,4,2) -> 50 | G11: =RIGHT(D11,3) -> 009
A12: FL250010 | B12: FL | C12: 250010 | D12: FL250010 | E12: =LEFT(D12,3) -> FL2 | F12: =MID(D12,4,2) -> 50 | G12: =RIGHT(D12,3) -> 010
A13: FL250011 | B13: FL | C13: 250011 | D13: FL250011 | E13: =LEFT(D13,3) -> FL2 | F13: =MID(D13,4,2) -> 50 | G13: =RIGHT(D13,3) -> 011
A14: FL250012 | B14: FL | C14: 250012 | D14: FL250012 | E14: =LEFT(D14,3) -> FL2 | F14: =MID(D14,4,2) -> 50 | G14: =RIGHT(D14,3) -> 012
... A1002: FL251000 | B1002: FL | C1002: 251000 | D1002: FL251000 | E1002: =LEFT(D1002,3) -> FL2 | F1002: =MID(D1002,4,2) -> 51 | G1002: =RIGHT(D1002,3) -> 000

Sheet Day 9 – Conditional Formatting 
A1: Conditional Formatting for Data Cleaning
A2: Refer Day6 worksheet

Sheet Day 10 – Descriptive Statistics
A1: No of projects | C1: Descriptive Statistics
A2: 13 | C2: Mean | D2: 8.715
A3: 10 | C3: Standard Error | D3: 0.17398289
A4: 16 | C4: Median | D4: 8
A5: 5 | C5: Mode | D5: 1
A6: 13 | C6: Standard Deviation | D6: 5.501822
A7: 8 | C7: Sample Variance | D7: 30.270045
A8: 10 | C8: Kurtosis | D8: -1.1352764
A9: 7 | C9: Skewness | D9: 0.24552448
A10: 2 | C10: Range | D10: 19
A11: 16 | C11: Minimum | D11: 1
A12: 20 | C12: Maximum | D12: 20
A13: 13 | C13: Sum | D13: 8715
A14: 16 | C14: Count | D14: 1000
A15: 17
A16: 14
A17: 5
A18: 7
A19: 1
A20: 13
A21: 1
A22: 15
A23: 3
A24: 14
A25: 9
A26: 15
... A1001: 15

Sheet Day 11 – Filtering, Sorting & E
A1: Name | B1: No of projects | D1: Top 5 | G1: Bottom 5
A2: Ms. Nicole Kidd | B2: 13 | D2: Name | E2: No of projects | G2: Name | H2: No of projects
A3: Vanessa Garcia | B3: 10 | D3: Joshua Holloway | E3: 20 | G3: Mark Ward | H3: 1
A4: Juan Nelson | B4: 16 | D4: Edwin Carter | E4: 20 | G4: Kimberly Allen | H4: 1
A5: Amanda Spencer | B5: 5 | D5: Dana Sanders | E5: 20 | G5: Nathan Soto | H5: 1
A6: Lynn Curtis DDS | B6: 13 | D6: Kenneth Arias | E6: 20 | G6: Megan Hudson | H6: 1
A7: Lisa Johnson | B7: 8 | D7: John Greene | E7: 20 | G7: Tracy White | H7: 1
A8: Eric Myers | B8: 10
A9: Ricky Graham | B9: 7
A10: Sean Martin | B10: 2
A11: Matthew Lloyd | B11: 16
A12: Gavin Randall | B12: 20
A13: Michelle Curtis | B13: 13
A14: Alice Schneider | B14: 16
A15: Phillip Shelton | B15: 17
A16: Edward Ferguson | B16: 14
A17: Wyatt Stout | B17: 5
A18: Laura Johnson | B18: 7
A19: Scott Burns | B19: 1
... A1001: Dawn Green | B1001: 15

Sheet Day 12 – Date & Time Functions
A1: In this dataset,there is no date & time data is available. So couldn't perform date & time functions.

Sheet Day 13 – Lookup Function
A1: Freelancer ID | B1: Name | C1: Gender | D1: Age | E1: Country | F1: Years_of_Experience | G1: Notes | H1: Status | I1: No of projects
A2: FL250001 | B2: =VLOOKUP(A:A,'global_freelancer Cleaned data'!A:O,2,FALSE) -> Ms. Nicole Kidd | C2: =VLOOKUP(A:A,'global_freelancer Cleaned data'!A1:O250,3,FALSE) -> Female | D2: =VLOOKUP(A:A,'global_freelancer Cleaned data'!A1:O250,4,FALSE) -> 52 | E2: =VLOOKUP(A:A,'global_freelancer Cleaned data'!A1:O250,5,FALSE) -> Italy | F2: =VLOOKUP(A:A,'global_freelancer Cleaned data'!A1:O250,8,FALSE) -> 11 | G2: =VLOOKUP(A:A,'global_freelancer Cleaned data'!A1:M250,13,FALSE) -> Reviewed | H2: =VLOOKUP(A:A,'global_freelancer Cleaned data'!A1:N250,14,FALSE) -> On Hold | I2: =VLOOKUP(A:A,'global_freelancer Cleaned data'!A1:O250,15,FALSE) -> 13
A3: FL250002 | B3: =VLOOKUP(A:A,'global_freelancer Cleaned data'!A:O,2,FALSE) -> Vanessa Garcia | C3: =VLOOKUP(A:A,'global_freelancer Cleaned data'!A2:O251,3,FALSE) -> Female | D3: =VLOOKUP(A:A,'global_freelancer Cleaned data'!A2:O251,4,FALSE) -> 52 | E3: =VLOOKUP(A:A,'global_freelancer Cleaned data'!A2:O251,5,FALSE) -> Australia | F3: =VLOOKUP(A:A,'global_freelancer Cleaned data'!A2:O251,8,FALSE) -> 34 | G3: =VLOOKUP(A:A,'global_freelancer Cleaned data'!A2:M251,13,FALSE) -> Reviewed | H3: =VLOOKUP(A:A,'global_freelancer Cleaned data'!A2:N251,14,FALSE) -> Completed | I3: =VLOOKUP(A:A,'global_freelancer Cleaned data'!A2:O251,15,FALSE) -> 10
A4: FL250003 | B4: =VLOOKUP(A:A,'global_freelancer Cleaned data'!A:O,2,FALSE) -> Juan Nelson | C4: =VLOOKUP(A:A,'global_freelancer Cleaned data'!A3:O252,3,FALSE) -> Male | D4: =VLOOKUP(A:A,'global_freelancer Cleaned data'!A3:O252,4,FALSE) -> 53 | E4: =VLOOKUP(A:A,'global_freelancer Cleaned data'!A3:O252,5,FALSE) -> Germany | F4: =VLOOKUP(A:A,'global_freelancer Cleaned data'!A3:O252,8,FALSE) -> 31 | G4: =VLOOKUP(A:A,'global_freelancer Cleaned data'!A3:M252,13,FALSE) -> Reviewed | H4: =VLOOKUP(A:A,'global_freelancer Cleaned data'!A3:N252,14,FALSE) -> Active | I4: =VLOOKUP(A:A,'global_freelancer Cleaned data'!A3:O252,15,FALSE) -> 16
A5: FL250004 | B5: =VLOOKUP(A:A,'global_freelancer Cleaned data'!A:O,2,FALSE) -> Amanda Spencer | C5: =VLOOKUP(A:A,'global_freelancer Cleaned data'!A4:O253,3,FALSE) -> Female | D5: =VLOOKUP(A:A,'global_freelancer Cleaned data'!A4:O253,4,FALSE) -> 38 | E5: =VLOOKUP(A:A,'global_freelancer Cleaned data'!A4:O253,5,FALSE) -> Australia | F5: =VLOOKUP(A:A,'global_freelancer Cleaned data'!A4:O253,8,FALSE) -> 4 | G5: =VLOOKUP(A:A,'global_freelancer Cleaned data'!A4:M253,13,FALSE) -> Reviewed | H5: =VLOOKUP(A:A,'global_freelancer Cleaned data'!A4:N253,14,FALSE) -> Completed | I5: =VLOOKUP(A:A,'global_freelancer Cleaned data'!A4:O253,15,FALSE) -> 5
